Traceback (most recent call last):
  File "/Users/hadiji/anaconda3/envs/py39/lib/python3.9/site-packages/jupyter_cache/executors/utils.py", line 58, in single_nb_execution
    executenb(
  File "/Users/hadiji/anaconda3/envs/py39/lib/python3.9/site-packages/nbclient/client.py", line 1314, in execute
    return NotebookClient(nb=nb, resources=resources, km=km, **kwargs).execute()
  File "/Users/hadiji/anaconda3/envs/py39/lib/python3.9/site-packages/jupyter_core/utils/__init__.py", line 165, in wrapped
    return loop.run_until_complete(inner)
  File "/Users/hadiji/anaconda3/envs/py39/lib/python3.9/asyncio/base_events.py", line 647, in run_until_complete
    return future.result()
  File "/Users/hadiji/anaconda3/envs/py39/lib/python3.9/site-packages/nbclient/client.py", line 709, in async_execute
    await self.async_execute_cell(
  File "/Users/hadiji/anaconda3/envs/py39/lib/python3.9/site-packages/nbclient/client.py", line 1062, in async_execute_cell
    await self._check_raise_for_error(cell, cell_index, exec_reply)
  File "/Users/hadiji/anaconda3/envs/py39/lib/python3.9/site-packages/nbclient/client.py", line 918, in _check_raise_for_error
    raise CellExecutionError.from_cell_and_msg(cell, exec_reply_content)
nbclient.exceptions.CellExecutionError: An error occurred while executing the following cell:
------------------
def train_perceptron(alg, data, t_lim=100_000): 
    converged = False
    t = 0 
    while not (converged) and t < t_lim:
        shuffled_indices = np.arange(len(data))
        #np.random.shuffle(shuffled_indices)
        clean_pass = True
        for i in shuffled_indices: 
                                                                                                                            if torch.dot(alg.w, x) * y < 1: 
                alg.update_margin_mistake(x, y)
                clean_pass = False
            t += 1
        if clean_pass: 
            converged = True
    return converged
------------------


[0;36m  File [0;32m<tokenize>:10[0;36m[0m
[0;31m    alg.update_margin_mistake(x, y)[0m
[0m    ^[0m
[0;31mIndentationError[0m[0;31m:[0m unindent does not match any outer indentation level


